[2025-04-04T23:21:06.117+0000] {local_task_job_runner.py:123} INFO - ::group::Pre task execution logs
[2025-04-04T23:21:06.156+0000] {taskinstance.py:2613} INFO - Dependencies all met for dep_context=non-requeueable deps ti=<TaskInstance: dag_with_postgres_operator_v04.delete_data_from_table scheduled__2025-04-03T00:00:00+00:00 [queued]>
[2025-04-04T23:21:06.181+0000] {taskinstance.py:2613} INFO - Dependencies all met for dep_context=requeueable deps ti=<TaskInstance: dag_with_postgres_operator_v04.delete_data_from_table scheduled__2025-04-03T00:00:00+00:00 [queued]>
[2025-04-04T23:21:06.182+0000] {taskinstance.py:2866} INFO - Starting attempt 1 of 6
[2025-04-04T23:21:06.208+0000] {taskinstance.py:2889} INFO - Executing <Task(PostgresOperator): delete_data_from_table> on 2025-04-03 00:00:00+00:00
[2025-04-04T23:21:06.219+0000] {logging_mixin.py:190} WARNING - /home/***/.local/lib/python3.12/site-packages/***/task/task_runner/standard_task_runner.py:70 DeprecationWarning: This process (pid=1910) is multi-threaded, use of fork() may lead to deadlocks in the child.
[2025-04-04T23:21:06.221+0000] {standard_task_runner.py:72} INFO - Started process 1911 to run task
[2025-04-04T23:21:06.219+0000] {standard_task_runner.py:104} INFO - Running: ['***', 'tasks', 'run', 'dag_with_postgres_operator_v04', 'delete_data_from_table', 'scheduled__2025-04-03T00:00:00+00:00', '--job-id', '874', '--raw', '--subdir', 'DAGS_FOLDER/dag_with_postgres_operator.py', '--cfg-path', '/tmp/tmp20c0uc09']
[2025-04-04T23:21:06.223+0000] {standard_task_runner.py:105} INFO - Job 874: Subtask delete_data_from_table
[2025-04-04T23:21:06.302+0000] {task_command.py:467} INFO - Running <TaskInstance: dag_with_postgres_operator_v04.delete_data_from_table scheduled__2025-04-03T00:00:00+00:00 [running]> on host ba06481f48a9
[2025-04-04T23:21:06.528+0000] {taskinstance.py:3132} INFO - Exporting env vars: AIRFLOW_CTX_DAG_OWNER='acilrestu12' AIRFLOW_CTX_DAG_ID='dag_with_postgres_operator_v04' AIRFLOW_CTX_TASK_ID='delete_data_from_table' AIRFLOW_CTX_EXECUTION_DATE='2025-04-03T00:00:00+00:00' AIRFLOW_CTX_TRY_NUMBER='1' AIRFLOW_CTX_DAG_RUN_ID='scheduled__2025-04-03T00:00:00+00:00'
[2025-04-04T23:21:06.531+0000] {taskinstance.py:731} INFO - ::endgroup::
[2025-04-04T23:21:06.569+0000] {sql.py:278} INFO - Executing: 
            INSERT INTO dag_runs (dt, dag_id, run_id)
            VALUES ('2025-04-03', 'dag_with_postgres_operator_v04', 'scheduled__2025-04-03T00:00:00+00:00');
        
[2025-04-04T23:21:06.585+0000] {base.py:84} INFO - Retrieving connection 'postgres_localhost'
[2025-04-04T23:21:06.602+0000] {base.py:84} INFO - Retrieving connection 'postgres_localhost'
[2025-04-04T23:21:06.620+0000] {sql.py:544} INFO - Running statement: 
            INSERT INTO dag_runs (dt, dag_id, run_id)
            VALUES ('2025-04-03', 'dag_with_postgres_operator_v04', 'scheduled__2025-04-03T00:00:00+00:00');
        , parameters: None
[2025-04-04T23:21:06.630+0000] {taskinstance.py:3311} ERROR - Task failed with exception
Traceback (most recent call last):
  File "/home/airflow/.local/lib/python3.12/site-packages/airflow/models/taskinstance.py", line 767, in _execute_task
    result = _execute_callable(context=context, **execute_callable_kwargs)
             ^^^^^^^^^^^^^^^^^^^^^^^^^^^^^^^^^^^^^^^^^^^^^^^^^^^^^^^^^^^^^
  File "/home/airflow/.local/lib/python3.12/site-packages/airflow/models/taskinstance.py", line 733, in _execute_callable
    return ExecutionCallableRunner(
           ^^^^^^^^^^^^^^^^^^^^^^^^
  File "/home/airflow/.local/lib/python3.12/site-packages/airflow/utils/operator_helpers.py", line 252, in run
    return self.func(*args, **kwargs)
           ^^^^^^^^^^^^^^^^^^^^^^^^^^
  File "/home/airflow/.local/lib/python3.12/site-packages/airflow/models/baseoperator.py", line 417, in wrapper
    return func(self, *args, **kwargs)
           ^^^^^^^^^^^^^^^^^^^^^^^^^^^
  File "/home/airflow/.local/lib/python3.12/site-packages/airflow/providers/common/sql/operators/sql.py", line 284, in execute
    output = hook.run(
             ^^^^^^^^^
  File "/home/airflow/.local/lib/python3.12/site-packages/airflow/providers/common/sql/hooks/sql.py", line 489, in run
    self._run_command(cur, sql_statement, parameters)
  File "/home/airflow/.local/lib/python3.12/site-packages/airflow/providers/common/sql/hooks/sql.py", line 549, in _run_command
    cur.execute(sql_statement)
psycopg2.errors.UniqueViolation: duplicate key value violates unique constraint "dag_runs_pkey"
DETAIL:  Key (dt, dag_id)=(2025-04-03, dag_with_postgres_operator_v04) already exists.

[2025-04-04T23:21:06.656+0000] {taskinstance.py:1225} INFO - Marking task as UP_FOR_RETRY. dag_id=dag_with_postgres_operator_v04, task_id=delete_data_from_table, run_id=scheduled__2025-04-03T00:00:00+00:00, execution_date=20250403T000000, start_date=20250404T232106, end_date=20250404T232106
[2025-04-04T23:21:06.696+0000] {taskinstance.py:340} INFO - ::group::Post task execution logs
[2025-04-04T23:21:06.698+0000] {standard_task_runner.py:124} ERROR - Failed to execute job 874 for task delete_data_from_table (duplicate key value violates unique constraint "dag_runs_pkey"
DETAIL:  Key (dt, dag_id)=(2025-04-03, dag_with_postgres_operator_v04) already exists.
; 1911)
Traceback (most recent call last):
  File "/home/airflow/.local/lib/python3.12/site-packages/airflow/task/task_runner/standard_task_runner.py", line 117, in _start_by_fork
    ret = args.func(args, dag=self.dag)
          ^^^^^^^^^^^^^^^^^^^^^^^^^^^^^
  File "/home/airflow/.local/lib/python3.12/site-packages/airflow/cli/cli_config.py", line 49, in command
    return func(*args, **kwargs)
           ^^^^^^^^^^^^^^^^^^^^^
  File "/home/airflow/.local/lib/python3.12/site-packages/airflow/utils/cli.py", line 116, in wrapper
    return f(*args, **kwargs)
           ^^^^^^^^^^^^^^^^^^
  File "/home/airflow/.local/lib/python3.12/site-packages/airflow/cli/commands/task_command.py", line 483, in task_run
    task_return_code = _run_task_by_selected_method(args, _dag, ti)
                       ^^^^^^^^^^^^^^^^^^^^^^^^^^^^^^^^^^^^^^^^^^^^
  File "/home/airflow/.local/lib/python3.12/site-packages/airflow/cli/commands/task_command.py", line 256, in _run_task_by_selected_method
    return _run_raw_task(args, ti)
           ^^^^^^^^^^^^^^^^^^^^^^^
  File "/home/airflow/.local/lib/python3.12/site-packages/airflow/cli/commands/task_command.py", line 341, in _run_raw_task
    return ti._run_raw_task(
           ^^^^^^^^^^^^^^^^^
  File "/home/airflow/.local/lib/python3.12/site-packages/airflow/utils/session.py", line 97, in wrapper
    return func(*args, session=session, **kwargs)
           ^^^^^^^^^^^^^^^^^^^^^^^^^^^^^^^^^^^^^^
  File "/home/airflow/.local/lib/python3.12/site-packages/airflow/models/taskinstance.py", line 3005, in _run_raw_task
    return _run_raw_task(
           ^^^^^^^^^^^^^^
  File "/home/airflow/.local/lib/python3.12/site-packages/airflow/models/taskinstance.py", line 273, in _run_raw_task
    TaskInstance._execute_task_with_callbacks(
  File "/home/airflow/.local/lib/python3.12/site-packages/airflow/models/taskinstance.py", line 3159, in _execute_task_with_callbacks
    result = self._execute_task(context, task_orig)
             ^^^^^^^^^^^^^^^^^^^^^^^^^^^^^^^^^^^^^^
  File "/home/airflow/.local/lib/python3.12/site-packages/airflow/models/taskinstance.py", line 3183, in _execute_task
    return _execute_task(self, context, task_orig)
           ^^^^^^^^^^^^^^^^^^^^^^^^^^^^^^^^^^^^^^^
  File "/home/airflow/.local/lib/python3.12/site-packages/airflow/models/taskinstance.py", line 767, in _execute_task
    result = _execute_callable(context=context, **execute_callable_kwargs)
             ^^^^^^^^^^^^^^^^^^^^^^^^^^^^^^^^^^^^^^^^^^^^^^^^^^^^^^^^^^^^^
  File "/home/airflow/.local/lib/python3.12/site-packages/airflow/models/taskinstance.py", line 733, in _execute_callable
    return ExecutionCallableRunner(
           ^^^^^^^^^^^^^^^^^^^^^^^^
  File "/home/airflow/.local/lib/python3.12/site-packages/airflow/utils/operator_helpers.py", line 252, in run
    return self.func(*args, **kwargs)
           ^^^^^^^^^^^^^^^^^^^^^^^^^^
  File "/home/airflow/.local/lib/python3.12/site-packages/airflow/models/baseoperator.py", line 417, in wrapper
    return func(self, *args, **kwargs)
           ^^^^^^^^^^^^^^^^^^^^^^^^^^^
  File "/home/airflow/.local/lib/python3.12/site-packages/airflow/providers/common/sql/operators/sql.py", line 284, in execute
    output = hook.run(
             ^^^^^^^^^
  File "/home/airflow/.local/lib/python3.12/site-packages/airflow/providers/common/sql/hooks/sql.py", line 489, in run
    self._run_command(cur, sql_statement, parameters)
  File "/home/airflow/.local/lib/python3.12/site-packages/airflow/providers/common/sql/hooks/sql.py", line 549, in _run_command
    cur.execute(sql_statement)
psycopg2.errors.UniqueViolation: duplicate key value violates unique constraint "dag_runs_pkey"
DETAIL:  Key (dt, dag_id)=(2025-04-03, dag_with_postgres_operator_v04) already exists.

[2025-04-04T23:21:06.720+0000] {local_task_job_runner.py:266} INFO - Task exited with return code 1
[2025-04-04T23:21:06.759+0000] {taskinstance.py:3895} INFO - 0 downstream tasks scheduled from follow-on schedule check
[2025-04-04T23:21:06.763+0000] {local_task_job_runner.py:245} INFO - ::endgroup::
