[2025-06-08T19:16:33.723+0000] {local_task_job_runner.py:123} INFO - ::group::Pre task execution logs
[2025-06-08T19:16:33.767+0000] {taskinstance.py:2613} INFO - Dependencies all met for dep_context=non-requeueable deps ti=<TaskInstance: dag_ml_pipeline_docker_operator_v01.docker_model_train_and_publish_task manual__2025-06-08T19:16:29.905791+00:00 [queued]>
[2025-06-08T19:16:33.795+0000] {taskinstance.py:2613} INFO - Dependencies all met for dep_context=requeueable deps ti=<TaskInstance: dag_ml_pipeline_docker_operator_v01.docker_model_train_and_publish_task manual__2025-06-08T19:16:29.905791+00:00 [queued]>
[2025-06-08T19:16:33.797+0000] {taskinstance.py:2866} INFO - Starting attempt 1 of 1
[2025-06-08T19:16:33.849+0000] {taskinstance.py:2889} INFO - Executing <Task(DockerOperator): docker_model_train_and_publish_task> on 2025-06-08 19:16:29.905791+00:00
[2025-06-08T19:16:33.872+0000] {standard_task_runner.py:104} INFO - Running: ['***', 'tasks', 'run', 'dag_ml_pipeline_docker_operator_v01', 'docker_model_train_and_publish_task', 'manual__2025-06-08T19:16:29.905791+00:00', '--job-id', '1413', '--raw', '--subdir', 'DAGS_FOLDER/ml_pipeline_with_docker_operator.py', '--cfg-path', '/tmp/tmpp7pdy1oo']
[2025-06-08T19:16:33.877+0000] {logging_mixin.py:190} WARNING - /home/***/.local/lib/python3.12/site-packages/***/task/task_runner/standard_task_runner.py:70 DeprecationWarning: This process (pid=23486) is multi-threaded, use of fork() may lead to deadlocks in the child.
[2025-06-08T19:16:33.877+0000] {standard_task_runner.py:105} INFO - Job 1413: Subtask docker_model_train_and_publish_task
[2025-06-08T19:16:33.880+0000] {standard_task_runner.py:72} INFO - Started process 23487 to run task
[2025-06-08T19:16:33.979+0000] {task_command.py:467} INFO - Running <TaskInstance: dag_ml_pipeline_docker_operator_v01.docker_model_train_and_publish_task manual__2025-06-08T19:16:29.905791+00:00 [running]> on host e9ff53ca7e24
[2025-06-08T19:16:34.118+0000] {taskinstance.py:3132} INFO - Exporting env vars: AIRFLOW_CTX_DAG_OWNER='acilrestu12' AIRFLOW_CTX_DAG_ID='dag_ml_pipeline_docker_operator_v01' AIRFLOW_CTX_TASK_ID='docker_model_train_and_publish_task' AIRFLOW_CTX_EXECUTION_DATE='2025-06-08T19:16:29.905791+00:00' AIRFLOW_CTX_TRY_NUMBER='1' AIRFLOW_CTX_DAG_RUN_ID='manual__2025-06-08T19:16:29.905791+00:00'
[2025-06-08T19:16:34.120+0000] {taskinstance.py:731} INFO - ::endgroup::
[2025-06-08T19:16:34.387+0000] {docker.py:157} ERROR - Failed to establish connection to Docker host unix://var/run/docker.sock: Error while fetching server API version: ('Connection aborted.', FileNotFoundError(2, 'No such file or directory'))
[2025-06-08T19:16:34.408+0000] {taskinstance.py:3311} ERROR - Task failed with exception
Traceback (most recent call last):
  File "/home/airflow/.local/lib/python3.12/site-packages/airflow/models/taskinstance.py", line 767, in _execute_task
    result = _execute_callable(context=context, **execute_callable_kwargs)
             ^^^^^^^^^^^^^^^^^^^^^^^^^^^^^^^^^^^^^^^^^^^^^^^^^^^^^^^^^^^^^
  File "/home/airflow/.local/lib/python3.12/site-packages/airflow/models/taskinstance.py", line 733, in _execute_callable
    return ExecutionCallableRunner(
           ^^^^^^^^^^^^^^^^^^^^^^^^
  File "/home/airflow/.local/lib/python3.12/site-packages/airflow/utils/operator_helpers.py", line 252, in run
    return self.func(*args, **kwargs)
           ^^^^^^^^^^^^^^^^^^^^^^^^^^
  File "/home/airflow/.local/lib/python3.12/site-packages/airflow/models/baseoperator.py", line 417, in wrapper
    return func(self, *args, **kwargs)
           ^^^^^^^^^^^^^^^^^^^^^^^^^^^
  File "/home/airflow/.local/lib/python3.12/site-packages/airflow/providers/docker/operators/docker.py", line 494, in execute
    if self.force_pull or not self.cli.images(name=self.image):
                              ^^^^^^^^
  File "/home/airflow/.local/lib/python3.12/site-packages/airflow/providers/docker/operators/docker.py", line 363, in cli
    return self.hook.api_client
           ^^^^^^^^^^^^^^^^^^^^
  File "/usr/local/lib/python3.12/functools.py", line 993, in __get__
    val = self.func(instance)
          ^^^^^^^^^^^^^^^^^^^
  File "/home/airflow/.local/lib/python3.12/site-packages/airflow/providers/docker/hooks/docker.py", line 161, in api_client
    raise AirflowException("Failed to establish connection to any given Docker hosts.")
airflow.exceptions.AirflowException: Failed to establish connection to any given Docker hosts.
[2025-06-08T19:16:34.418+0000] {taskinstance.py:1225} INFO - Marking task as FAILED. dag_id=dag_ml_pipeline_docker_operator_v01, task_id=docker_model_train_and_publish_task, run_id=manual__2025-06-08T19:16:29.905791+00:00, execution_date=20250608T191629, start_date=20250608T191633, end_date=20250608T191634
[2025-06-08T19:16:34.438+0000] {taskinstance.py:340} INFO - ::group::Post task execution logs
[2025-06-08T19:16:34.439+0000] {standard_task_runner.py:124} ERROR - Failed to execute job 1413 for task docker_model_train_and_publish_task (Failed to establish connection to any given Docker hosts.; 23487)
Traceback (most recent call last):
  File "/home/airflow/.local/lib/python3.12/site-packages/airflow/task/task_runner/standard_task_runner.py", line 117, in _start_by_fork
    ret = args.func(args, dag=self.dag)
          ^^^^^^^^^^^^^^^^^^^^^^^^^^^^^
  File "/home/airflow/.local/lib/python3.12/site-packages/airflow/cli/cli_config.py", line 49, in command
    return func(*args, **kwargs)
           ^^^^^^^^^^^^^^^^^^^^^
  File "/home/airflow/.local/lib/python3.12/site-packages/airflow/utils/cli.py", line 116, in wrapper
    return f(*args, **kwargs)
           ^^^^^^^^^^^^^^^^^^
  File "/home/airflow/.local/lib/python3.12/site-packages/airflow/cli/commands/task_command.py", line 483, in task_run
    task_return_code = _run_task_by_selected_method(args, _dag, ti)
                       ^^^^^^^^^^^^^^^^^^^^^^^^^^^^^^^^^^^^^^^^^^^^
  File "/home/airflow/.local/lib/python3.12/site-packages/airflow/cli/commands/task_command.py", line 256, in _run_task_by_selected_method
    return _run_raw_task(args, ti)
           ^^^^^^^^^^^^^^^^^^^^^^^
  File "/home/airflow/.local/lib/python3.12/site-packages/airflow/cli/commands/task_command.py", line 341, in _run_raw_task
    return ti._run_raw_task(
           ^^^^^^^^^^^^^^^^^
  File "/home/airflow/.local/lib/python3.12/site-packages/airflow/utils/session.py", line 97, in wrapper
    return func(*args, session=session, **kwargs)
           ^^^^^^^^^^^^^^^^^^^^^^^^^^^^^^^^^^^^^^
  File "/home/airflow/.local/lib/python3.12/site-packages/airflow/models/taskinstance.py", line 3005, in _run_raw_task
    return _run_raw_task(
           ^^^^^^^^^^^^^^
  File "/home/airflow/.local/lib/python3.12/site-packages/airflow/models/taskinstance.py", line 273, in _run_raw_task
    TaskInstance._execute_task_with_callbacks(
  File "/home/airflow/.local/lib/python3.12/site-packages/airflow/models/taskinstance.py", line 3159, in _execute_task_with_callbacks
    result = self._execute_task(context, task_orig)
             ^^^^^^^^^^^^^^^^^^^^^^^^^^^^^^^^^^^^^^
  File "/home/airflow/.local/lib/python3.12/site-packages/airflow/models/taskinstance.py", line 3183, in _execute_task
    return _execute_task(self, context, task_orig)
           ^^^^^^^^^^^^^^^^^^^^^^^^^^^^^^^^^^^^^^^
  File "/home/airflow/.local/lib/python3.12/site-packages/airflow/models/taskinstance.py", line 767, in _execute_task
    result = _execute_callable(context=context, **execute_callable_kwargs)
             ^^^^^^^^^^^^^^^^^^^^^^^^^^^^^^^^^^^^^^^^^^^^^^^^^^^^^^^^^^^^^
  File "/home/airflow/.local/lib/python3.12/site-packages/airflow/models/taskinstance.py", line 733, in _execute_callable
    return ExecutionCallableRunner(
           ^^^^^^^^^^^^^^^^^^^^^^^^
  File "/home/airflow/.local/lib/python3.12/site-packages/airflow/utils/operator_helpers.py", line 252, in run
    return self.func(*args, **kwargs)
           ^^^^^^^^^^^^^^^^^^^^^^^^^^
  File "/home/airflow/.local/lib/python3.12/site-packages/airflow/models/baseoperator.py", line 417, in wrapper
    return func(self, *args, **kwargs)
           ^^^^^^^^^^^^^^^^^^^^^^^^^^^
  File "/home/airflow/.local/lib/python3.12/site-packages/airflow/providers/docker/operators/docker.py", line 494, in execute
    if self.force_pull or not self.cli.images(name=self.image):
                              ^^^^^^^^
  File "/home/airflow/.local/lib/python3.12/site-packages/airflow/providers/docker/operators/docker.py", line 363, in cli
    return self.hook.api_client
           ^^^^^^^^^^^^^^^^^^^^
  File "/usr/local/lib/python3.12/functools.py", line 993, in __get__
    val = self.func(instance)
          ^^^^^^^^^^^^^^^^^^^
  File "/home/airflow/.local/lib/python3.12/site-packages/airflow/providers/docker/hooks/docker.py", line 161, in api_client
    raise AirflowException("Failed to establish connection to any given Docker hosts.")
airflow.exceptions.AirflowException: Failed to establish connection to any given Docker hosts.
[2025-06-08T19:16:34.480+0000] {local_task_job_runner.py:266} INFO - Task exited with return code 1
[2025-06-08T19:16:34.506+0000] {taskinstance.py:3895} INFO - 0 downstream tasks scheduled from follow-on schedule check
[2025-06-08T19:16:34.511+0000] {local_task_job_runner.py:245} INFO - ::endgroup::
