[2025-05-19T18:36:56.503+0000] {local_task_job_runner.py:123} INFO - ::group::Pre task execution logs
[2025-05-19T18:36:56.544+0000] {taskinstance.py:2613} INFO - Dependencies all met for dep_context=non-requeueable deps ti=<TaskInstance: dag_with_postgres_hooks_v06.postgres_to_s3 scheduled__2025-05-17T00:00:00+00:00 [queued]>
[2025-05-19T18:36:56.571+0000] {taskinstance.py:2613} INFO - Dependencies all met for dep_context=requeueable deps ti=<TaskInstance: dag_with_postgres_hooks_v06.postgres_to_s3 scheduled__2025-05-17T00:00:00+00:00 [queued]>
[2025-05-19T18:36:56.572+0000] {taskinstance.py:2866} INFO - Starting attempt 1 of 6
[2025-05-19T18:36:56.607+0000] {taskinstance.py:2889} INFO - Executing <Task(PythonOperator): postgres_to_s3> on 2025-05-17 00:00:00+00:00
[2025-05-19T18:36:56.623+0000] {standard_task_runner.py:104} INFO - Running: ['***', 'tasks', 'run', 'dag_with_postgres_hooks_v06', 'postgres_to_s3', 'scheduled__2025-05-17T00:00:00+00:00', '--job-id', '1255', '--raw', '--subdir', 'DAGS_FOLDER/dag_with_postgres_hooks.py', '--cfg-path', '/tmp/tmpkcknof_d']
[2025-05-19T18:36:56.626+0000] {logging_mixin.py:190} WARNING - /home/***/.local/lib/python3.12/site-packages/***/task/task_runner/standard_task_runner.py:70 DeprecationWarning: This process (pid=5435) is multi-threaded, use of fork() may lead to deadlocks in the child.
[2025-05-19T18:36:56.627+0000] {standard_task_runner.py:105} INFO - Job 1255: Subtask postgres_to_s3
[2025-05-19T18:36:56.627+0000] {standard_task_runner.py:72} INFO - Started process 5436 to run task
[2025-05-19T18:36:56.751+0000] {task_command.py:467} INFO - Running <TaskInstance: dag_with_postgres_hooks_v06.postgres_to_s3 scheduled__2025-05-17T00:00:00+00:00 [running]> on host e9ff53ca7e24
[2025-05-19T18:36:57.027+0000] {taskinstance.py:3132} INFO - Exporting env vars: AIRFLOW_CTX_DAG_OWNER='acilrestu12' AIRFLOW_CTX_DAG_ID='dag_with_postgres_hooks_v06' AIRFLOW_CTX_TASK_ID='postgres_to_s3' AIRFLOW_CTX_EXECUTION_DATE='2025-05-17T00:00:00+00:00' AIRFLOW_CTX_TRY_NUMBER='1' AIRFLOW_CTX_DAG_RUN_ID='scheduled__2025-05-17T00:00:00+00:00'
[2025-05-19T18:36:57.029+0000] {taskinstance.py:731} INFO - ::endgroup::
[2025-05-19T18:36:57.073+0000] {logging_mixin.py:190} WARNING - /home/***/.local/lib/python3.12/site-packages/***/utils/operator_helpers.py:175 AirflowContextDeprecationWarning: Accessing 'next_ds_nodash' from the template is deprecated and will be removed in a future version. Please use '{{ data_interval_end | ds_nodash }}' instead.
[2025-05-19T18:36:57.094+0000] {base.py:84} INFO - Retrieving connection 'postgres_localhost'
[2025-05-19T18:36:57.127+0000] {logging_mixin.py:190} WARNING - --- Logging error ---
[2025-05-19T18:36:57.130+0000] {logging_mixin.py:190} WARNING - Traceback (most recent call last):
[2025-05-19T18:36:57.133+0000] {logging_mixin.py:190} WARNING -   File "/usr/local/lib/python3.12/logging/__init__.py", line 1160, in emit
    msg = self.format(record)
          ^^^^^^^^^^^^^^^^^^^
[2025-05-19T18:36:57.135+0000] {logging_mixin.py:190} WARNING -   File "/usr/local/lib/python3.12/logging/__init__.py", line 999, in format
    return fmt.format(record)
           ^^^^^^^^^^^^^^^^^^
[2025-05-19T18:36:57.136+0000] {logging_mixin.py:190} WARNING -   File "/usr/local/lib/python3.12/logging/__init__.py", line 703, in format
    record.message = record.getMessage()
                     ^^^^^^^^^^^^^^^^^^^
[2025-05-19T18:36:57.138+0000] {logging_mixin.py:190} WARNING -   File "/usr/local/lib/python3.12/logging/__init__.py", line 392, in getMessage
    msg = msg % self.args
          ~~~~^~~~~~~~~~~
[2025-05-19T18:36:57.139+0000] {logging_mixin.py:190} WARNING - TypeError: not all arguments converted during string formatting
[2025-05-19T18:36:57.140+0000] {logging_mixin.py:190} WARNING - Call stack:
[2025-05-19T18:36:57.153+0000] {logging_mixin.py:190} WARNING -   File "/home/***/.local/bin/***", line 8, in <module>
    sys.exit(main())
[2025-05-19T18:36:57.154+0000] {logging_mixin.py:190} WARNING -   File "/home/***/.local/lib/python3.12/site-packages/***/__main__.py", line 62, in main
    args.func(args)
[2025-05-19T18:36:57.155+0000] {logging_mixin.py:190} WARNING -   File "/home/***/.local/lib/python3.12/site-packages/***/cli/cli_config.py", line 49, in command
    return func(*args, **kwargs)
[2025-05-19T18:36:57.157+0000] {logging_mixin.py:190} WARNING -   File "/home/***/.local/lib/python3.12/site-packages/***/utils/cli.py", line 116, in wrapper
    return f(*args, **kwargs)
[2025-05-19T18:36:57.159+0000] {logging_mixin.py:190} WARNING -   File "/home/***/.local/lib/python3.12/site-packages/***/utils/providers_configuration_loader.py", line 55, in wrapped_function
    return func(*args, **kwargs)
[2025-05-19T18:36:57.160+0000] {logging_mixin.py:190} WARNING -   File "/home/***/.local/lib/python3.12/site-packages/***/cli/commands/scheduler_command.py", line 59, in scheduler
    run_command_with_daemon_option(
[2025-05-19T18:36:57.161+0000] {logging_mixin.py:190} WARNING -   File "/home/***/.local/lib/python3.12/site-packages/***/cli/commands/daemon_utils.py", line 86, in run_command_with_daemon_option
    callback()
[2025-05-19T18:36:57.162+0000] {logging_mixin.py:190} WARNING -   File "/home/***/.local/lib/python3.12/site-packages/***/cli/commands/scheduler_command.py", line 62, in <lambda>
    callback=lambda: _run_scheduler_job(args),
[2025-05-19T18:36:57.163+0000] {logging_mixin.py:190} WARNING -   File "/home/***/.local/lib/python3.12/site-packages/***/cli/commands/scheduler_command.py", line 48, in _run_scheduler_job
    run_job(job=job_runner.job, execute_callable=job_runner._execute)
[2025-05-19T18:36:57.164+0000] {logging_mixin.py:190} WARNING -   File "/home/***/.local/lib/python3.12/site-packages/***/utils/session.py", line 97, in wrapper
    return func(*args, session=session, **kwargs)
[2025-05-19T18:36:57.166+0000] {logging_mixin.py:190} WARNING -   File "/home/***/.local/lib/python3.12/site-packages/***/jobs/job.py", line 421, in run_job
    return execute_job(job, execute_callable=execute_callable)
[2025-05-19T18:36:57.167+0000] {logging_mixin.py:190} WARNING -   File "/home/***/.local/lib/python3.12/site-packages/***/jobs/job.py", line 450, in execute_job
    ret = execute_callable()
[2025-05-19T18:36:57.168+0000] {logging_mixin.py:190} WARNING -   File "/home/***/.local/lib/python3.12/site-packages/***/jobs/scheduler_job_runner.py", line 978, in _execute
    executor.start()
[2025-05-19T18:36:57.170+0000] {logging_mixin.py:190} WARNING -   File "/home/***/.local/lib/python3.12/site-packages/***/executors/local_executor.py", line 392, in start
    self.impl.start()
[2025-05-19T18:36:57.171+0000] {logging_mixin.py:190} WARNING -   File "/home/***/.local/lib/python3.12/site-packages/***/executors/local_executor.py", line 330, in start
    worker.start()
[2025-05-19T18:36:57.174+0000] {logging_mixin.py:190} WARNING -   File "/usr/local/lib/python3.12/multiprocessing/process.py", line 121, in start
    self._popen = self._Popen(self)
[2025-05-19T18:36:57.175+0000] {logging_mixin.py:190} WARNING -   File "/usr/local/lib/python3.12/multiprocessing/context.py", line 224, in _Popen
    return _default_context.get_context().Process._Popen(process_obj)
[2025-05-19T18:36:57.176+0000] {logging_mixin.py:190} WARNING -   File "/usr/local/lib/python3.12/multiprocessing/context.py", line 282, in _Popen
    return Popen(process_obj)
[2025-05-19T18:36:57.178+0000] {logging_mixin.py:190} WARNING -   File "/usr/local/lib/python3.12/multiprocessing/popen_fork.py", line 19, in __init__
    self._launch(process_obj)
[2025-05-19T18:36:57.179+0000] {logging_mixin.py:190} WARNING -   File "/usr/local/lib/python3.12/multiprocessing/popen_fork.py", line 71, in _launch
    code = process_obj._bootstrap(parent_sentinel=child_r)
[2025-05-19T18:36:57.180+0000] {logging_mixin.py:190} WARNING -   File "/usr/local/lib/python3.12/multiprocessing/process.py", line 314, in _bootstrap
    self.run()
[2025-05-19T18:36:57.181+0000] {logging_mixin.py:190} WARNING -   File "/home/***/.local/lib/python3.12/site-packages/***/executors/local_executor.py", line 80, in run
    return super().run()
[2025-05-19T18:36:57.182+0000] {logging_mixin.py:190} WARNING -   File "/usr/local/lib/python3.12/multiprocessing/process.py", line 108, in run
    self._target(*self._args, **self._kwargs)
[2025-05-19T18:36:57.183+0000] {logging_mixin.py:190} WARNING -   File "/home/***/.local/lib/python3.12/site-packages/***/traces/tracer.py", line 58, in wrapper
    return func(*args, **kwargs)
[2025-05-19T18:36:57.184+0000] {logging_mixin.py:190} WARNING -   File "/home/***/.local/lib/python3.12/site-packages/***/executors/local_executor.py", line 211, in do_work
    self.execute_work(key=key, command=command)
[2025-05-19T18:36:57.186+0000] {logging_mixin.py:190} WARNING -   File "/home/***/.local/lib/python3.12/site-packages/***/traces/tracer.py", line 58, in wrapper
    return func(*args, **kwargs)
[2025-05-19T18:36:57.188+0000] {logging_mixin.py:190} WARNING -   File "/home/***/.local/lib/python3.12/site-packages/***/executors/local_executor.py", line 100, in execute_work
    state = self._execute_work_in_fork(command)
[2025-05-19T18:36:57.190+0000] {logging_mixin.py:190} WARNING -   File "/home/***/.local/lib/python3.12/site-packages/***/traces/tracer.py", line 58, in wrapper
    return func(*args, **kwargs)
[2025-05-19T18:36:57.191+0000] {logging_mixin.py:190} WARNING -   File "/home/***/.local/lib/python3.12/site-packages/***/executors/local_executor.py", line 142, in _execute_work_in_fork
    args.func(args)
[2025-05-19T18:36:57.192+0000] {logging_mixin.py:190} WARNING -   File "/home/***/.local/lib/python3.12/site-packages/***/cli/cli_config.py", line 49, in command
    return func(*args, **kwargs)
[2025-05-19T18:36:57.193+0000] {logging_mixin.py:190} WARNING -   File "/home/***/.local/lib/python3.12/site-packages/***/utils/cli.py", line 116, in wrapper
    return f(*args, **kwargs)
[2025-05-19T18:36:57.194+0000] {logging_mixin.py:190} WARNING -   File "/home/***/.local/lib/python3.12/site-packages/***/cli/commands/task_command.py", line 483, in task_run
    task_return_code = _run_task_by_selected_method(args, _dag, ti)
[2025-05-19T18:36:57.194+0000] {logging_mixin.py:190} WARNING -   File "/home/***/.local/lib/python3.12/site-packages/***/cli/commands/task_command.py", line 254, in _run_task_by_selected_method
    return _run_task_by_local_task_job(args, ti)
[2025-05-19T18:36:57.195+0000] {logging_mixin.py:190} WARNING -   File "/home/***/.local/lib/python3.12/site-packages/***/cli/commands/task_command.py", line 322, in _run_task_by_local_task_job
    ret = run_job(job=job_runner.job, execute_callable=job_runner._execute)
[2025-05-19T18:36:57.196+0000] {logging_mixin.py:190} WARNING -   File "/home/***/.local/lib/python3.12/site-packages/***/utils/session.py", line 97, in wrapper
    return func(*args, session=session, **kwargs)
[2025-05-19T18:36:57.197+0000] {logging_mixin.py:190} WARNING -   File "/home/***/.local/lib/python3.12/site-packages/***/jobs/job.py", line 421, in run_job
    return execute_job(job, execute_callable=execute_callable)
[2025-05-19T18:36:57.198+0000] {logging_mixin.py:190} WARNING -   File "/home/***/.local/lib/python3.12/site-packages/***/jobs/job.py", line 450, in execute_job
    ret = execute_callable()
[2025-05-19T18:36:57.198+0000] {logging_mixin.py:190} WARNING -   File "/home/***/.local/lib/python3.12/site-packages/***/jobs/local_task_job_runner.py", line 171, in _execute
    self.task_runner.start()
[2025-05-19T18:36:57.200+0000] {logging_mixin.py:190} WARNING -   File "/home/***/.local/lib/python3.12/site-packages/***/task/task_runner/standard_task_runner.py", line 55, in start
    self.process = self._start_by_fork()
[2025-05-19T18:36:57.201+0000] {logging_mixin.py:190} WARNING -   File "/home/***/.local/lib/python3.12/site-packages/***/task/task_runner/standard_task_runner.py", line 117, in _start_by_fork
    ret = args.func(args, dag=self.dag)
[2025-05-19T18:36:57.202+0000] {logging_mixin.py:190} WARNING -   File "/home/***/.local/lib/python3.12/site-packages/***/cli/cli_config.py", line 49, in command
    return func(*args, **kwargs)
[2025-05-19T18:36:57.204+0000] {logging_mixin.py:190} WARNING -   File "/home/***/.local/lib/python3.12/site-packages/***/utils/cli.py", line 116, in wrapper
    return f(*args, **kwargs)
[2025-05-19T18:36:57.205+0000] {logging_mixin.py:190} WARNING -   File "/home/***/.local/lib/python3.12/site-packages/***/cli/commands/task_command.py", line 483, in task_run
    task_return_code = _run_task_by_selected_method(args, _dag, ti)
[2025-05-19T18:36:57.206+0000] {logging_mixin.py:190} WARNING -   File "/home/***/.local/lib/python3.12/site-packages/***/cli/commands/task_command.py", line 256, in _run_task_by_selected_method
    return _run_raw_task(args, ti)
[2025-05-19T18:36:57.208+0000] {logging_mixin.py:190} WARNING -   File "/home/***/.local/lib/python3.12/site-packages/***/cli/commands/task_command.py", line 341, in _run_raw_task
    return ti._run_raw_task(
[2025-05-19T18:36:57.209+0000] {logging_mixin.py:190} WARNING -   File "/home/***/.local/lib/python3.12/site-packages/***/utils/session.py", line 97, in wrapper
    return func(*args, session=session, **kwargs)
[2025-05-19T18:36:57.210+0000] {logging_mixin.py:190} WARNING -   File "/home/***/.local/lib/python3.12/site-packages/***/models/taskinstance.py", line 3005, in _run_raw_task
    return _run_raw_task(
[2025-05-19T18:36:57.211+0000] {logging_mixin.py:190} WARNING -   File "/home/***/.local/lib/python3.12/site-packages/***/models/taskinstance.py", line 273, in _run_raw_task
    TaskInstance._execute_task_with_callbacks(
[2025-05-19T18:36:57.213+0000] {logging_mixin.py:190} WARNING -   File "/home/***/.local/lib/python3.12/site-packages/***/models/taskinstance.py", line 3159, in _execute_task_with_callbacks
    result = self._execute_task(context, task_orig)
[2025-05-19T18:36:57.220+0000] {logging_mixin.py:190} WARNING -   File "/home/***/.local/lib/python3.12/site-packages/***/models/taskinstance.py", line 3183, in _execute_task
    return _execute_task(self, context, task_orig)
[2025-05-19T18:36:57.221+0000] {logging_mixin.py:190} WARNING -   File "/home/***/.local/lib/python3.12/site-packages/***/models/taskinstance.py", line 767, in _execute_task
    result = _execute_callable(context=context, **execute_callable_kwargs)
[2025-05-19T18:36:57.222+0000] {logging_mixin.py:190} WARNING -   File "/home/***/.local/lib/python3.12/site-packages/***/models/taskinstance.py", line 733, in _execute_callable
    return ExecutionCallableRunner(
[2025-05-19T18:36:57.224+0000] {logging_mixin.py:190} WARNING -   File "/home/***/.local/lib/python3.12/site-packages/***/utils/operator_helpers.py", line 252, in run
    return self.func(*args, **kwargs)
[2025-05-19T18:36:57.225+0000] {logging_mixin.py:190} WARNING -   File "/home/***/.local/lib/python3.12/site-packages/***/models/baseoperator.py", line 417, in wrapper
    return func(self, *args, **kwargs)
[2025-05-19T18:36:57.226+0000] {logging_mixin.py:190} WARNING -   File "/home/***/.local/lib/python3.12/site-packages/***/operators/python.py", line 238, in execute
    return_value = self.execute_callable()
[2025-05-19T18:36:57.230+0000] {logging_mixin.py:190} WARNING -   File "/home/***/.local/lib/python3.12/site-packages/***/operators/python.py", line 256, in execute_callable
    return runner.run(*self.op_args, **self.op_kwargs)
[2025-05-19T18:36:57.232+0000] {logging_mixin.py:190} WARNING -   File "/home/***/.local/lib/python3.12/site-packages/***/utils/operator_helpers.py", line 252, in run
    return self.func(*args, **kwargs)
[2025-05-19T18:36:57.233+0000] {logging_mixin.py:190} WARNING -   File "/opt/***/dags/dag_with_postgres_hooks.py", line 50, in postges_to_s3
    logging.info('Saved orders data in the file:', f'dags/get_orders_{ds_nodash}.txt')
[2025-05-19T18:36:57.235+0000] {logging_mixin.py:190} WARNING -   File "/usr/local/lib/python3.12/logging/__init__.py", line 2216, in info
    root.info(msg, *args, **kwargs)
[2025-05-19T18:36:57.236+0000] {logging_mixin.py:190} WARNING -   File "/usr/local/lib/python3.12/logging/__init__.py", line 1539, in info
    self._log(INFO, msg, args, **kwargs)
[2025-05-19T18:36:57.239+0000] {logging_mixin.py:190} WARNING -   File "/usr/local/lib/python3.12/logging/__init__.py", line 1684, in _log
    self.handle(record)
[2025-05-19T18:36:57.240+0000] {logging_mixin.py:190} WARNING -   File "/usr/local/lib/python3.12/logging/__init__.py", line 1700, in handle
    self.callHandlers(record)
[2025-05-19T18:36:57.242+0000] {logging_mixin.py:190} WARNING -   File "/usr/local/lib/python3.12/logging/__init__.py", line 1762, in callHandlers
    hdlr.handle(record)
[2025-05-19T18:36:57.243+0000] {logging_mixin.py:190} WARNING -   File "/usr/local/lib/python3.12/logging/__init__.py", line 1028, in handle
    self.emit(record)
[2025-05-19T18:36:57.245+0000] {logging_mixin.py:190} WARNING -   File "/home/***/.local/lib/python3.12/site-packages/***/utils/log/file_task_handler.py", line 274, in emit
    self.handler.emit(record)
[2025-05-19T18:36:57.246+0000] {logging_mixin.py:190} WARNING - Message: 'Saved orders data in the file:'
Arguments: ('dags/get_orders_20250517.txt',)
[2025-05-19T18:36:57.265+0000] {base.py:84} INFO - Retrieving connection 'minio_conn'
[2025-05-19T18:36:57.267+0000] {connection_wrapper.py:325} INFO - AWS Connection (conn_id='minio_conn', conn_type='aws') credentials retrieved from login and password.
[2025-05-19T18:36:58.149+0000] {hook.py:208} WARNING - Data lineage tracking is disabled. Register a hook lineage reader to start tracking hook lineage.
[2025-05-19T18:36:58.150+0000] {dag_with_postgres_hooks.py:60} INFO - Orders file /tmp/tmpyq_wfoog20250517 has been pushed to S3
[2025-05-19T18:36:58.151+0000] {python.py:240} INFO - Done. Returned value was: None
[2025-05-19T18:36:58.172+0000] {taskinstance.py:340} INFO - ::group::Post task execution logs
[2025-05-19T18:36:58.175+0000] {taskinstance.py:352} INFO - Marking task as SUCCESS. dag_id=dag_with_postgres_hooks_v06, task_id=postgres_to_s3, run_id=scheduled__2025-05-17T00:00:00+00:00, execution_date=20250517T000000, start_date=20250519T183656, end_date=20250519T183658
[2025-05-19T18:36:58.255+0000] {local_task_job_runner.py:266} INFO - Task exited with return code 0
[2025-05-19T18:36:58.288+0000] {taskinstance.py:3895} INFO - 0 downstream tasks scheduled from follow-on schedule check
[2025-05-19T18:36:58.292+0000] {local_task_job_runner.py:245} INFO - ::endgroup::
